Workbook
Name concepto_salarios: 'LISTA SALARIOS'!$A$2:$A$149
Name LISTA_PRECIOS: 'LISTAS PRECIOS'!$B$2:$B$35
Name LISTA_SERVICIOS: 'LISTAS PRECIOS'!$A$2:$A$35
Name Inflables: 'TARIFAS INFLABLES'!$A$2:$A$11
Name Horas_toro: 'TARIFAS TORO'!$A$2:$A$7
Name monto_salarios: 'LISTA SALARIOS'!$B$2:$B$149

Sheet DASHBOARD
A1: 0 | B1: AÑO | C1: 2026
B3: INGRESO TOTAL ANUAL | D3: EGRESO TOTAL ANUAL | F3: GASTO TOTAL ANUAL | H3: SALARIO TOTAL ANUAL | J3: MARGEN TOTAL ANUAL | L3: UTILIDAD TOTAL ANUAL
B4: =SUM(C6:C17) -> 153724 | D4: =SUM(D6:E17) -> 91519 | F4: =SUM(D6:D17) -> 48011 | H4: =SUM(E6:E17) -> 43508 | J4: =(B4-D4)/B4 -> 0.4046538 | L4: =B4-D4 -> 62205
B5: Mes | C5: Ingresos | D5: Gastos | E5: Salarios | F5: Margen de ganancia | G5: Utilidad neta | H5: Ingresos toro | I5: Ingresos inflables | J5: Ingresos sonido | K5: Ingresos pista
B6: enero | C6: =SUMIFS(INGRESOS!L:L,INGRESOS!M:M,$B6,INGRESOS!N:N,$C$1) -> 55234 | D6: =SUMIFS(GASTOS!C:C,GASTOS!E:E,$B6,GASTOS!F:F,$C$1) -> 31421 | E6: =SUMIFS(SALARIOS!H:H,SALARIOS!I:I,$B6,SALARIOS!J:J,$C$1) -> 17308 | F6: =IFERROR((C6-D6-E6)/C6,0) -> 0.11777166 | G6: =C6-D6-E6 -> 6505 | H6: =SUMIFS(INGRESOS!L:L,INGRESOS!M:M,$B6,INGRESOS!N:N,$C$1,INGRESOS!B:B,"Toro") -> 22784 | I6: =SUMIFS(INGRESOS!L:L,INGRESOS!M:M,$B6,INGRESOS!N:N,$C$1,INGRESOS!B:B,"Inflable") -> 16450 | J6: =SUMIFS(INGRESOS!L:L,INGRESOS!M:M,$B6,INGRESOS!N:N,$C$1,INGRESOS!B:B,"Sonido") -> 16000 | K6: =SUMIFS(INGRESOS!L:L,INGRESOS!M:M,$B6,INGRESOS!N:N,$C$1,INGRESOS!B:B,"Pista") -> 0
B7: febrero | C7: =SUMIFS(INGRESOS!L:L,INGRESOS!M:M,$B7,INGRESOS!N:N,$C$1) -> 95240 | D7: =SUMIFS(GASTOS!C:C,GASTOS!E:E,$B7,GASTOS!F:F,$C$1) -> 13419 | E7: =SUMIFS(SALARIOS!H:H,SALARIOS!I:I,$B7,SALARIOS!J:J,$C$1) -> 25250 | F7: =IFERROR((C7-D7-E7)/C7,0) -> 0.59398362 | G7: =C7-D7-E7 -> 56571 | H7: =SUMIFS(INGRESOS!L:L,INGRESOS!M:M,$B7,INGRESOS!N:N,$C$1,INGRESOS!B:B,"Toro") -> 33650 | I7: =SUMIFS(INGRESOS!L:L,INGRESOS!M:M,$B7,INGRESOS!N:N,$C$1,INGRESOS!B:B,"Inflable") -> 19250 | J7: =SUMIFS(INGRESOS!L:L,INGRESOS!M:M,$B7,INGRESOS!N:N,$C$1,INGRESOS!B:B,"Sonido") -> 34840 | K7: =SUMIFS(INGRESOS!L:L,INGRESOS!M:M,$B7,INGRESOS!N:N,$C$1,INGRESOS!B:B,"Pista") -> 7500
B8: marzo | C8: =SUMIFS(INGRESOS!L:L,INGRESOS!M:M,$B8,INGRESOS!N:N,$C$1) -> 3250 | D8: =SUMIFS(GASTOS!C:C,GASTOS!E:E,$B8,GASTOS!F:F,$C$1) -> 3171 | E8: =SUMIFS(SALARIOS!H:H,SALARIOS!I:I,$B8,SALARIOS!J:J,$C$1) -> 950 | F8: =IFERROR((C8-D8-E8)/C8,0) -> -0.268 | G8: =C8-D8-E8 -> -871 | H8: =SUMIFS(INGRESOS!L:L,INGRESOS!M:M,$B8,INGRESOS!N:N,$C$1,INGRESOS!B:B,"Toro") -> 2200 | I8: =SUMIFS(INGRESOS!L:L,INGRESOS!M:M,$B8,INGRESOS!N:N,$C$1,INGRESOS!B:B,"Inflable") -> 1050 | J8: =SUMIFS(INGRESOS!L:L,INGRESOS!M:M,$B8,INGRESOS!N:N,$C$1,INGRESOS!B:B,"Sonido") -> 0 | K8: =SUMIFS(INGRESOS!L:L,INGRESOS!M:M,$B8,INGRESOS!N:N,$C$1,INGRESOS!B:B,"Pista") -> 0
B9: abril | C9: =SUMIFS(INGRESOS!L:L,INGRESOS!M:M,$B9,INGRESOS!N:N,$C$1) -> 0 | D9: =SUMIFS(GASTOS!C:C,GASTOS!E:E,$B9,GASTOS!F:F,$C$1) -> 0 | E9: =SUMIFS(SALARIOS!H:H,SALARIOS!I:I,$B9,SALARIOS!J:J,$C$1) -> 0 | F9: =IFERROR((C9-D9-E9)/C9,0) -> 0 | G9: =C9-D9-E9 -> 0 | H9: =SUMIFS(INGRESOS!L:L,INGRESOS!M:M,$B9,INGRESOS!N:N,$C$1,INGRESOS!B:B,"Toro") -> 0 | I9: =SUMIFS(INGRESOS!L:L,INGRESOS!M:M,$B9,INGRESOS!N:N,$C$1,INGRESOS!B:B,"Inflable") -> 0 | J9: =SUMIFS(INGRESOS!L:L,INGRESOS!M:M,$B9,INGRESOS!N:N,$C$1,INGRESOS!B:B,"Sonido") -> 0 | K9: =SUMIFS(INGRESOS!L:L,INGRESOS!M:M,$B9,INGRESOS!N:N,$C$1,INGRESOS!B:B,"Pista") -> 0
B10: mayo | C10: =SUMIFS(INGRESOS!L:L,INGRESOS!M:M,$B10,INGRESOS!N:N,$C$1) -> 0 | D10: =SUMIFS(GASTOS!C:C,GASTOS!E:E,$B10,GASTOS!F:F,$C$1) -> 0 | E10: =SUMIFS(SALARIOS!H:H,SALARIOS!I:I,$B10,SALARIOS!J:J,$C$1) -> 0 | F10: =IFERROR((C10-D10-E10)/C10,0) -> 0 | G10: =C10-D10-E10 -> 0 | H10: =SUMIFS(INGRESOS!L:L,INGRESOS!M:M,$B10,INGRESOS!N:N,$C$1,INGRESOS!B:B,"Toro") -> 0 | I10: =SUMIFS(INGRESOS!L:L,INGRESOS!M:M,$B10,INGRESOS!N:N,$C$1,INGRESOS!B:B,"Inflable") -> 0 | J10: =SUMIFS(INGRESOS!L:L,INGRESOS!M:M,$B10,INGRESOS!N:N,$C$1,INGRESOS!B:B,"Sonido") -> 0 | K10: =SUMIFS(INGRESOS!L:L,INGRESOS!M:M,$B10,INGRESOS!N:N,$C$1,INGRESOS!B:B,"Pista") -> 0
B11: junio | C11: =SUMIFS(INGRESOS!L:L,INGRESOS!M:M,$B11,INGRESOS!N:N,$C$1) -> 0 | D11: =SUMIFS(GASTOS!C:C,GASTOS!E:E,$B11,GASTOS!F:F,$C$1) -> 0 | E11: =SUMIFS(SALARIOS!H:H,SALARIOS!I:I,$B11,SALARIOS!J:J,$C$1) -> 0 | F11: =IFERROR((C11-D11-E11)/C11,0) -> 0 | G11: =C11-D11-E11 -> 0 | H11: =SUMIFS(INGRESOS!L:L,INGRESOS!M:M,$B11,INGRESOS!N:N,$C$1,INGRESOS!B:B,"Toro") -> 0 | I11: =SUMIFS(INGRESOS!L:L,INGRESOS!M:M,$B11,INGRESOS!N:N,$C$1,INGRESOS!B:B,"Inflable") -> 0 | J11: =SUMIFS(INGRESOS!L:L,INGRESOS!M:M,$B11,INGRESOS!N:N,$C$1,INGRESOS!B:B,"Sonido") -> 0 | K11: =SUMIFS(INGRESOS!L:L,INGRESOS!M:M,$B11,INGRESOS!N:N,$C$1,INGRESOS!B:B,"Pista") -> 0
B12: julio | C12: =SUMIFS(INGRESOS!L:L,INGRESOS!M:M,$B12,INGRESOS!N:N,$C$1) -> 0 | D12: =SUMIFS(GASTOS!C:C,GASTOS!E:E,$B12,GASTOS!F:F,$C$1) -> 0 | E12: =SUMIFS(SALARIOS!H:H,SALARIOS!I:I,$B12,SALARIOS!J:J,$C$1) -> 0 | F12: =IFERROR((C12-D12-E12)/C12,0) -> 0 | G12: =C12-D12-E12 -> 0 | H12: =SUMIFS(INGRESOS!L:L,INGRESOS!M:M,$B12,INGRESOS!N:N,$C$1,INGRESOS!B:B,"Toro") -> 0 | I12: =SUMIFS(INGRESOS!L:L,INGRESOS!M:M,$B12,INGRESOS!N:N,$C$1,INGRESOS!B:B,"Inflable") -> 0 | J12: =SUMIFS(INGRESOS!L:L,INGRESOS!M:M,$B12,INGRESOS!N:N,$C$1,INGRESOS!B:B,"Sonido") -> 0 | K12: =SUMIFS(INGRESOS!L:L,INGRESOS!M:M,$B12,INGRESOS!N:N,$C$1,INGRESOS!B:B,"Pista") -> 0
B13: agosto | C13: =SUMIFS(INGRESOS!L:L,INGRESOS!M:M,$B13,INGRESOS!N:N,$C$1) -> 0 | D13: =SUMIFS(GASTOS!C:C,GASTOS!E:E,$B13,GASTOS!F:F,$C$1) -> 0 | E13: =SUMIFS(SALARIOS!H:H,SALARIOS!I:I,$B13,SALARIOS!J:J,$C$1) -> 0 | F13: =IFERROR((C13-D13-E13)/C13,0) -> 0 | G13: =C13-D13-E13 -> 0 | H13: =SUMIFS(INGRESOS!L:L,INGRESOS!M:M,$B13,INGRESOS!N:N,$C$1,INGRESOS!B:B,"Toro") -> 0 | I13: =SUMIFS(INGRESOS!L:L,INGRESOS!M:M,$B13,INGRESOS!N:N,$C$1,INGRESOS!B:B,"Inflable") -> 0 | J13: =SUMIFS(INGRESOS!L:L,INGRESOS!M:M,$B13,INGRESOS!N:N,$C$1,INGRESOS!B:B,"Sonido") -> 0 | K13: =SUMIFS(INGRESOS!L:L,INGRESOS!M:M,$B13,INGRESOS!N:N,$C$1,INGRESOS!B:B,"Pista") -> 0
B14: septiembre | C14: =SUMIFS(INGRESOS!L:L,INGRESOS!M:M,$B14,INGRESOS!N:N,$C$1) -> 0 | D14: =SUMIFS(GASTOS!C:C,GASTOS!E:E,$B14,GASTOS!F:F,$C$1) -> 0 | E14: =SUMIFS(SALARIOS!H:H,SALARIOS!I:I,$B14,SALARIOS!J:J,$C$1) -> 0 | F14: =IFERROR((C14-D14-E14)/C14,0) -> 0 | G14: =C14-D14-E14 -> 0 | H14: =SUMIFS(INGRESOS!L:L,INGRESOS!M:M,$B14,INGRESOS!N:N,$C$1,INGRESOS!B:B,"Toro") -> 0 | I14: =SUMIFS(INGRESOS!L:L,INGRESOS!M:M,$B14,INGRESOS!N:N,$C$1,INGRESOS!B:B,"Inflable") -> 0 | J14: =SUMIFS(INGRESOS!L:L,INGRESOS!M:M,$B14,INGRESOS!N:N,$C$1,INGRESOS!B:B,"Sonido") -> 0 | K14: =SUMIFS(INGRESOS!L:L,INGRESOS!M:M,$B14,INGRESOS!N:N,$C$1,INGRESOS!B:B,"Pista") -> 0
B15: octubre | C15: =SUMIFS(INGRESOS!L:L,INGRESOS!M:M,$B15,INGRESOS!N:N,$C$1) -> 0 | D15: =SUMIFS(GASTOS!C:C,GASTOS!E:E,$B15,GASTOS!F:F,$C$1) -> 0 | E15: =SUMIFS(SALARIOS!H:H,SALARIOS!I:I,$B15,SALARIOS!J:J,$C$1) -> 0 | F15: =IFERROR((C15-D15-E15)/C15,0) -> 0 | G15: =C15-D15-E15 -> 0 | H15: =SUMIFS(INGRESOS!L:L,INGRESOS!M:M,$B15,INGRESOS!N:N,$C$1,INGRESOS!B:B,"Toro") -> 0 | I15: =SUMIFS(INGRESOS!L:L,INGRESOS!M:M,$B15,INGRESOS!N:N,$C$1,INGRESOS!B:B,"Inflable") -> 0 | J15: =SUMIFS(INGRESOS!L:L,INGRESOS!M:M,$B15,INGRESOS!N:N,$C$1,INGRESOS!B:B,"Sonido") -> 0 | K15: =SUMIFS(INGRESOS!L:L,INGRESOS!M:M,$B15,INGRESOS!N:N,$C$1,INGRESOS!B:B,"Pista") -> 0
B16: noviembre | C16: =SUMIFS(INGRESOS!L:L,INGRESOS!M:M,$B16,INGRESOS!N:N,$C$1) -> 0 | D16: =SUMIFS(GASTOS!C:C,GASTOS!E:E,$B16,GASTOS!F:F,$C$1) -> 0 | E16: =SUMIFS(SALARIOS!H:H,SALARIOS!I:I,$B16,SALARIOS!J:J,$C$1) -> 0 | F16: =IFERROR((C16-D16-E16)/C16,0) -> 0 | G16: =C16-D16-E16 -> 0 | H16: =SUMIFS(INGRESOS!L:L,INGRESOS!M:M,$B16,INGRESOS!N:N,$C$1,INGRESOS!B:B,"Toro") -> 0 | I16: =SUMIFS(INGRESOS!L:L,INGRESOS!M:M,$B16,INGRESOS!N:N,$C$1,INGRESOS!B:B,"Inflable") -> 0 | J16: =SUMIFS(INGRESOS!L:L,INGRESOS!M:M,$B16,INGRESOS!N:N,$C$1,INGRESOS!B:B,"Sonido") -> 0 | K16: =SUMIFS(INGRESOS!L:L,INGRESOS!M:M,$B16,INGRESOS!N:N,$C$1,INGRESOS!B:B,"Pista") -> 0
B17: diciembre | C17: =SUMIFS(INGRESOS!L:L,INGRESOS!M:M,$B17,INGRESOS!N:N,$C$1) -> 0 | D17: =SUMIFS(GASTOS!C:C,GASTOS!E:E,$B17,GASTOS!F:F,$C$1) -> 0 | E17: =SUMIFS(SALARIOS!H:H,SALARIOS!I:I,$B17,SALARIOS!J:J,$C$1) -> 0 | F17: =IFERROR((C17-D17-E17)/C17,0) -> 0 | G17: =C17-D17-E17 -> 0 | H17: =SUMIFS(INGRESOS!L:L,INGRESOS!M:M,$B17,INGRESOS!N:N,$C$1,INGRESOS!B:B,"Toro") -> 0 | I17: =SUMIFS(INGRESOS!L:L,INGRESOS!M:M,$B17,INGRESOS!N:N,$C$1,INGRESOS!B:B,"Inflable") -> 0 | J17: =SUMIFS(INGRESOS!L:L,INGRESOS!M:M,$B17,INGRESOS!N:N,$C$1,INGRESOS!B:B,"Sonido") -> 0 | K17: =SUMIFS(INGRESOS!L:L,INGRESOS!M:M,$B17,INGRESOS!N:N,$C$1,INGRESOS!B:B,"Pista") -> 0
B19: Concepto | C19: Monto
B20: Gastos | C20: =SUM(D6:D17) -> 48011
B21: Salarios | C21: =SUM(E6:E17) -> 43508
B22: Utilidad | C22: =SUM(G6:G17) -> 62205
B42: MES | C42: febrero | D42: INGRESO MENSUAL | E42: SALARIO MENSUAL | F42: GASTO MENSUAL | G42: EGRESO MENSUAL | H42: UTILIDAD MENSUAL
D43: =SUM(C44:C53,E44:E50,G44:G49) -> 87740 | E43: =SUM(I44:I54) -> 25250 | F43: =SUM(K44:K60) -> 13419 | G43: =E43+F43 -> 38669 | H43: =D43-G43 -> 49071
B44: Spiderman_cubo | C44: =SUMIFS(INGRESOS!L:L,INGRESOS!N:N,$C$1,INGRESOS!M:M,$C$42,INGRESOS!D:D,$B44) -> 1200 | D44: Party | E44: =SUMIFS(INGRESOS!L:L,INGRESOS!N:N,$C$1,INGRESOS!M:M,$C$42,INGRESOS!D:D,$D44) -> 20890 | F44: 1 HORA TORO | G44: =SUMIFS(INGRESOS!L:L,INGRESOS!N:N,$C$1,INGRESOS!M:M,$C$42,INGRESOS!D:D,$F44) -> 0 | H44: Jesús | I44: =SUMIFS(SALARIOS!H:H,SALARIOS!J:J,$C$1,SALARIOS!I:I,$C$42,SALARIOS!B:B,$H44) -> 4560 | J44: Artículos de sonido | K44: =SUMIFS(GASTOS!C:C,GASTOS!F:F,$C$1,GASTOS!E:E,$C$42,GASTOS!G:G,$J44) -> 58
B45: Mickey | C45: =SUMIFS(INGRESOS!L:L,INGRESOS!N:N,$C$1,INGRESOS!M:M,$C$42,INGRESOS!D:D,$B45) -> 600 | D45: Plata | E45: =SUMIFS(INGRESOS!L:L,INGRESOS!N:N,$C$1,INGRESOS!M:M,$C$42,INGRESOS!D:D,$D45) -> 3300 | F45: 2 HORAS TORO | G45: =SUMIFS(INGRESOS!L:L,INGRESOS!N:N,$C$1,INGRESOS!M:M,$C$42,INGRESOS!D:D,$F45) -> 3700 | H45: Angel | I45: =SUMIFS(SALARIOS!H:H,SALARIOS!J:J,$C$1,SALARIOS!I:I,$C$42,SALARIOS!B:B,$H45) -> 2210 | J45: Artículos de reparación | K45: =SUMIFS(GASTOS!C:C,GASTOS!F:F,$C$1,GASTOS!E:E,$C$42,GASTOS!G:G,$J45) -> 28
B46: Minions | C46: =SUMIFS(INGRESOS!L:L,INGRESOS!N:N,$C$1,INGRESOS!M:M,$C$42,INGRESOS!D:D,$B46) -> 1300 | D46: Chiquidisco | E46: =SUMIFS(INGRESOS!L:L,INGRESOS!N:N,$C$1,INGRESOS!M:M,$C$42,INGRESOS!D:D,$D46) -> 0 | F46: 3 HORAS TORO | G46: =SUMIFS(INGRESOS!L:L,INGRESOS!N:N,$C$1,INGRESOS!M:M,$C$42,INGRESOS!D:D,$F46) -> 9600 | H46: Carlos | I46: =SUMIFS(SALARIOS!H:H,SALARIOS!J:J,$C$1,SALARIOS!I:I,$C$42,SALARIOS!B:B,$H46) -> 4090 | J46: Artículos de toro | K46: =SUMIFS(GASTOS!C:C,GASTOS!F:F,$C$1,GASTOS!E:E,$C$42,GASTOS!G:G,$J46) -> 0
B47: Princesas | C47: =SUMIFS(INGRESOS!L:L,INGRESOS!N:N,$C$1,INGRESOS!M:M,$C$42,INGRESOS!D:D,$B47) -> 1900 | D47: Deluxe | E47: =SUMIFS(INGRESOS!L:L,INGRESOS!N:N,$C$1,INGRESOS!M:M,$C$42,INGRESOS!D:D,$D47) -> 0 | F47: 4 HORAS TORO | G47: =SUMIFS(INGRESOS!L:L,INGRESOS!N:N,$C$1,INGRESOS!M:M,$C$42,INGRESOS!D:D,$F47) -> 20350 | H47: Sebastián | I47: =SUMIFS(SALARIOS!H:H,SALARIOS!J:J,$C$1,SALARIOS!I:I,$C$42,SALARIOS!B:B,$H47) -> 1060 | J47: Gasolina | K47: =SUMIFS(GASTOS!C:C,GASTOS!F:F,$C$1,GASTOS!E:E,$C$42,GASTOS!G:G,$J47) -> 3120
B48: Castillo | C48: =SUMIFS(INGRESOS!L:L,INGRESOS!N:N,$C$1,INGRESOS!M:M,$C$42,INGRESOS!D:D,$B48) -> 2650 | D48: Premium | E48: =SUMIFS(INGRESOS!L:L,INGRESOS!N:N,$C$1,INGRESOS!M:M,$C$42,INGRESOS!D:D,$D48) -> 3700 | F48: 5 HORAS TORO | G48: =SUMIFS(INGRESOS!L:L,INGRESOS!N:N,$C$1,INGRESOS!M:M,$C$42,INGRESOS!D:D,$F48) -> 0 | H48: Jesualdo | I48: =SUMIFS(SALARIOS!H:H,SALARIOS!J:J,$C$1,SALARIOS!I:I,$C$42,SALARIOS!B:B,$H48) -> 0 | J48: Herramientas | K48: =SUMIFS(GASTOS!C:C,GASTOS!F:F,$C$1,GASTOS!E:E,$C$42,GASTOS!G:G,$J48) -> 0
B49: Spiderman_circular | C49: =SUMIFS(INGRESOS!L:L,INGRESOS!N:N,$C$1,INGRESOS!M:M,$C$42,INGRESOS!D:D,$B49) -> 1600 | D49: Oro | E49: =SUMIFS(INGRESOS!L:L,INGRESOS!N:N,$C$1,INGRESOS!M:M,$C$42,INGRESOS!D:D,$D49) -> 0 | F49: 6 HORAS TORO | G49: =SUMIFS(INGRESOS!L:L,INGRESOS!N:N,$C$1,INGRESOS!M:M,$C$42,INGRESOS!D:D,$F49) -> 0 | H49: Rodrigo | I49: =SUMIFS(SALARIOS!H:H,SALARIOS!J:J,$C$1,SALARIOS!I:I,$C$42,SALARIOS!B:B,$H49) -> 690 | J49: Impuestos | K49: =SUMIFS(GASTOS!C:C,GASTOS!F:F,$C$1,GASTOS!E:E,$C$42,GASTOS!G:G,$J49) -> 400
B50: Barbie | C50: =SUMIFS(INGRESOS!L:L,INGRESOS!N:N,$C$1,INGRESOS!M:M,$C$42,INGRESOS!D:D,$B50) -> 800 | D50: Diamante | E50: =SUMIFS(INGRESOS!L:L,INGRESOS!N:N,$C$1,INGRESOS!M:M,$C$42,INGRESOS!D:D,$D50) -> 6950 | H50: Marco | I50: =SUMIFS(SALARIOS!H:H,SALARIOS!J:J,$C$1,SALARIOS!I:I,$C$42,SALARIOS!B:B,$H50) -> 3625 | J50: Mantenimiento almacén | K50: =SUMIFS(GASTOS!C:C,GASTOS!F:F,$C$1,GASTOS!E:E,$C$42,GASTOS!G:G,$J50) -> 0
B51: Princesas_circular | C51: =SUMIFS(INGRESOS!L:L,INGRESOS!N:N,$C$1,INGRESOS!M:M,$C$42,INGRESOS!D:D,$B51) -> 800 | H51: Juan | I51: =SUMIFS(SALARIOS!H:H,SALARIOS!J:J,$C$1,SALARIOS!I:I,$C$42,SALARIOS!B:B,$H51) -> 5785 | J51: Publicidad | K51: =SUMIFS(GASTOS!C:C,GASTOS!F:F,$C$1,GASTOS!E:E,$C$42,GASTOS!G:G,$J51) -> 0
B52: Superheróes | C52: =SUMIFS(INGRESOS!L:L,INGRESOS!N:N,$C$1,INGRESOS!M:M,$C$42,INGRESOS!D:D,$B52) -> 4400 | H52: Alejandro | I52: =SUMIFS(SALARIOS!H:H,SALARIOS!J:J,$C$1,SALARIOS!I:I,$C$42,SALARIOS!B:B,$H52) -> 0 | J52: Renta Sonido | K52: =SUMIFS(GASTOS!C:C,GASTOS!F:F,$C$1,GASTOS!E:E,$C$42,GASTOS!G:G,$J52) -> 1900
B53: Obstaculos | C53: =SUMIFS(INGRESOS!L:L,INGRESOS!N:N,$C$1,INGRESOS!M:M,$C$42,INGRESOS!D:D,$B53) -> 4000 | H53: Axel | I53: =SUMIFS(SALARIOS!H:H,SALARIOS!J:J,$C$1,SALARIOS!I:I,$C$42,SALARIOS!B:B,$H53) -> 2130 | J53: Reparación audio | K53: =SUMIFS(GASTOS!C:C,GASTOS!F:F,$C$1,GASTOS!E:E,$C$42,GASTOS!G:G,$J53) -> 0
H54: Ricardo | I54: =SUMIFS(SALARIOS!H:H,SALARIOS!J:J,$C$1,SALARIOS!I:I,$C$42,SALARIOS!B:B,$H54) -> 1100 | J54: Reparaciones extra | K54: =SUMIFS(GASTOS!C:C,GASTOS!F:F,$C$1,GASTOS!E:E,$C$42,GASTOS!G:G,$J54) -> 0
B55: {=SORT(B44:C53,2,TRUE)} -> Mickey | C55: 600 | D55: {=SORT(D44:E50,2,TRUE)} -> Chiquidisco | E55: 0 | J55: Reparación Toros | K55: =SUMIFS(GASTOS!C:C,GASTOS!F:F,$C$1,GASTOS!E:E,$C$42,GASTOS!G:G,$J55) -> 0
B56: Barbie | C56: 800 | D56: Deluxe | E56: 0 | F56: {=SORT(F44:G49,2,TRUE)} -> 1 HORA TORO | G56: 0 | H56: {=SORT(H44:I54,2,TRUE)} -> Jesualdo | I56: 0 | J56: Reparación vehículos | K56: =SUMIFS(GASTOS!C:C,GASTOS!F:F,$C$1,GASTOS!E:E,$C$42,GASTOS!G:G,$J56) -> 0
B57: Princesas_circular | C57: 800 | D57: Oro | E57: 0 | F57: 5 HORAS TORO | G57: 0 | H57: Alejandro | I57: 0 | J57: Salarios extra | K57: =SUMIFS(GASTOS!C:C,GASTOS!F:F,$C$1,GASTOS!E:E,$C$42,GASTOS!G:G,$J57) -> 5950
B58: Spiderman_cubo | C58: 1200 | D58: Plata | E58: 3300 | F58: 6 HORAS TORO | G58: 0 | H58: Rodrigo | I58: 690 | J58: Saldo | K58: =SUMIFS(GASTOS!C:C,GASTOS!F:F,$C$1,GASTOS!E:E,$C$42,GASTOS!G:G,$J58) -> 150
B59: Minions | C59: 1300 | D59: Premium | E59: 3700 | F59: 2 HORAS TORO | G59: 3700 | H59: Sebastián | I59: 1060 | J59: Suministros toro | K59: =SUMIFS(GASTOS!C:C,GASTOS!F:F,$C$1,GASTOS!E:E,$C$42,GASTOS!G:G,$J59) -> 180
B60: Spiderman_circular | C60: 1600 | D60: Diamante | E60: 6950 | F60: 3 HORAS TORO | G60: 9600 | H60: Ricardo | I60: 1100 | J60: Suministros audio | K60: =SUMIFS(GASTOS!C:C,GASTOS!F:F,$C$1,GASTOS!E:E,$C$42,GASTOS!G:G,$J60) -> 1633
B61: Princesas | C61: 1900 | D61: Party | E61: 20890 | F61: 4 HORAS TORO | G61: 20350 | H61: Axel | I61: 2130
...

Sheet MATRIZ
A1: 0 | B1: 46079
P2: CUENTAS CON SEBAS
A3: INGRESOS | B3: CONCEPTO | C3: ANTICIPO | D3: RECIBIÓ ANTICIPO | E3: LIQUIDACIÓN | F3: RECIBIÓ LIQUIDACIÓN | H3: GASTOS | I3: CONCEPTO | J3: SOCIO | L3: Salario | M3: Concepto | N3: Trabajador | P3: INGRESOS | Q3: =SUM(INGRESOS[INGRESOS]) -> 600 | S3: GASTOS SEBAS | T3: =SUMIF(GASTOS[SOCIO],"Sebastián",GASTOS[GASTOS]) -> 0
A4: =IFERROR(__xludf.DUMMYFUNCTION("IFNA(FILTER(INGRESOS!L:L,INGRESOS!C:C=B1),0)"),600.0) -> 600 | B4: =IFERROR(__xludf.DUMMYFUNCTION("IFNA(FILTER(INGRESOS!D:D,INGRESOS!C:C=B1),""-"")"),"Superheróes") -> Superheróes | C4: =IFERROR(__xludf.DUMMYFUNCTION("IFNA(FILTER(INGRESOS!H:H,INGRESOS!C:C=B1),0)"),400.0) -> 400 | D4: =IFERROR(__xludf.DUMMYFUNCTION("IFNA(FILTER(INGRESOS!I:I,INGRESOS!C:C=B1),""-"")"),"Angel") -> Angel | E4: =IFERROR(__xludf.DUMMYFUNCTION("IFNA(FILTER(INGRESOS!J:J,INGRESOS!C:C=B1),0)"),200.0) -> 200 | F4: =IFERROR(__xludf.DUMMYFUNCTION("IFNA(FILTER(INGRESOS!K:K,INGRESOS!C:C=B1),""-"")"),"Carlos") -> Carlos | H4: =IFERROR(__xludf.DUMMYFUNCTION("IFNA(FILTER(GASTOS!C:C,GASTOS!A:A=B1),0)"),0.0) -> 0 | I4: =IFERROR(__xludf.DUMMYFUNCTION("IFNA(FILTER(GASTOS!B:B,GASTOS!A:A=B1),""-"")"),"-") -> - | J4: =IFERROR(__xludf.DUMMYFUNCTION("IFNA(FILTER(GASTOS!D:D,GASTOS!A:A=B1),""-"")"),"-") -> - | L4: =IFERROR(__xludf.DUMMYFUNCTION("ifna(FILTER(SALARIOS!H:H,SALARIOS!A:A=$B$1),0)"),240.0) -> 240 | M4: =IFERROR(__xludf.DUMMYFUNCTION("IFNA(FILTER(SALARIOS!D:D,SALARIOS!A:A=$B$1),""-"")"),"Superheroes solo dejar y recoger") -> Superheroes solo dejar y recoger | N4: =IFERROR(__xludf.DUMMYFUNCTION("IFNA(FILTER(SALARIOS!B:B,SALARIOS!A:A=$B$1),""-"")"),"Juan") -> Juan | P4: GASTOS | Q4: =SUM(GASTOS[GASTOS]) -> 0 | S4: GASTOS CARLOS | T4: =SUMIF(GASTOS[SOCIO],"Carlos",GASTOS[GASTOS]) -> 0
P5: SALARIOS | Q5: =SUM(SALARIOS[Salario]) -> 240
P6: SALARIOS EMPLEADOS | Q6: =Q5-T12-T13-T7 -> 240 | S6: GASTOS ANGEL | T6: =SUMIF(GASTOS[SOCIO],"Angel",GASTOS[GASTOS]) -> 0
P7: EGRESOS | Q7: =Q4+Q5 -> 240 | S7: SALARIO SEBAS | T7: =SUMIF(SALARIOS[Trabajador],"Sebastián",SALARIOS[Salario]) -> 0
P8: UTILIDAD NETA | Q8: =Q3-Q7 -> 360 | S8: SALARIOS EXCEPTO SEBAS | T8: =Q6-T7 -> 240
P9: UTILIDAD SOCIO | Q9: =Q8/2 -> 180 | S9: INGRESOS SEBAS | T9: =SUMIF(INGRESOS[RECIBIÓ ANTICIPO],"Sebastián",INGRESOS[ANTICIPO])+SUMIF(INGRESOS[RECIBIÓ LIQUIDACIÓN],"Sebastián",INGRESOS[LIQUIDACIÓN]) -> 0
P10: SALDO AQUINO | Q10: =Q9+T7+T3-T9+Q6 -> 420 | S10: INGRESOS CARLOS | T10: =SUMIF(INGRESOS[RECIBIÓ ANTICIPO],"Carlos",INGRESOS[ANTICIPO])+SUMIF(INGRESOS[RECIBIÓ LIQUIDACIÓN],"Carlos",INGRESOS[LIQUIDACIÓN]) -> 200
P11: SALDO VASQUEZ | Q11: =Q9+T4+T6-T10-T11+T12+T13 -> -420 | S11: INGRESOS ANGEL | T11: =SUMIF(INGRESOS[RECIBIÓ ANTICIPO],"Angel",INGRESOS[ANTICIPO])+SUMIF(INGRESOS[RECIBIÓ LIQUIDACIÓN],"Angel",INGRESOS[LIQUIDACIÓN]) -> 400
P12: MARGEN DE GANANCIA | Q12: =(Q8/Q3) -> 0.6 | S12: SALARIO ANGEL | T12: =SUMIF(SALARIOS[Trabajador],"Angel",SALARIOS[Salario]) -> 0
S13: SALARIO CARLOS | T13: =SUMIF(SALARIOS[Trabajador],"Carlos",SALARIOS[Salario]) -> 0
P16: CUENTAS CON CHARLY | S16: Java | T16: Sebas
P18: GANANCIAS | Q18: =Q9 -> 180 | S18: 209 | T18: 350
P19: GANANCIAS CADA QUIEN | Q19: =Q18/2 -> 90 | S19: 1540 | T19: 603
P20: TIENE CHARLY | Q20: =T10 -> 200 | S20: 3147 | T20: 225.5
P21: TIENE ANGEL | Q21: =T11+Q11 -> -20 | S21: =SUM(S18:S20) -> 4896 | T21: 1500 | V21: =S21-T23 -> -1927.5
P22: GASTOS CHARLY | Q22: =T4 -> 0 | T22: 4145
P23: GASTOS ANGEL | Q23: =T6 -> 0 | T23: =SUM(T18:T22) -> 6823.5
P24: SALARIO CARLOS | Q24: =T13 -> 0
P25: SALARIO ANGEL | Q25: =T12 -> 0
P26: EXTRA ANGEL | Q26: 0
P27: EXTRA CHARLY | Q27: 0
P28: UTILIDAD CARLOS | Q28: =Q19+Q24+Q27+Q22-Q20 -> -110
P29: UTILIDAD ANGEL | Q29: =Q19+Q25+Q26+Q23-Q21 -> 110

Sheet INGRESOS
A1: 00000000000000000003 | B1: SERVICIO | C1: FECHA | D1: DESCRIPCIÓN | E1: PRECIO | F1: AUMENTO | G1: DESCUENTO | H1: ANTICIPO | I1: RECIBIÓ ANTICIPO | J1: LIQUIDACIÓN | K1: RECIBIÓ | L1: MONTO | M1: Mes | N1: Año
A2: {=XLOOKUP(B2,SERVICIOS!B:B,SERVICIOS!A:A,"")} -> S01 | B2: Toro | C2: 45955 | D2: 2 horas toro | E2: {=XLOOKUP($D:$D,LISTA_SERVICIOS,LISTA_PRECIOS,0)} -> 2200 | F2: 0 | G2: 200 | H2: 0 | J2: =E2+F2-G2-H2 -> 2000 | K2: Carlos | L2: =E2+F2-G2 -> 2000 | M2: =IF(C2="","",TEXT(C2,"mmmm")) -> octubre | N2: =IF(C2="","",YEAR(C2)) -> 2025
A3: {=XLOOKUP(B3,SERVICIOS!B:B,SERVICIOS!A:A,"")} -> S03 | B3: Sonido | C3: 45955 | D3: Party | E3: {=XLOOKUP($D:$D,LISTA_SERVICIOS,LISTA_PRECIOS,0)} -> 2800 | F3: 0 | G3: 2180 | H3: 0 | J3: =E3+F3-G3-H3 -> 620 | K3: Carlos | L3: =E3+F3-G3 -> 620 | M3: =IF(C3="","",TEXT(C3,"mmmm")) -> octubre | N3: =IF(C3="","",YEAR(C3)) -> 2025
A4: {=XLOOKUP(B4,SERVICIOS!B:B,SERVICIOS!A:A,"")} -> S02 | B4: Inflable | C4: 45955 | D4: Princesas | E4: {=XLOOKUP($D:$D,LISTA_SERVICIOS,LISTA_PRECIOS,0)} -> 650 | F4: 0 | G4: 0 | H4: 500 | I4: Angel | J4: =E4+F4-G4-H4 -> 150 | K4: Sebastián | L4: =E4+F4-G4 -> 650 | M4: =IF(C4="","",TEXT(C4,"mmmm")) -> octubre | N4: =IF(C4="","",YEAR(C4)) -> 2025
A5: {=XLOOKUP(B5,SERVICIOS!B:B,SERVICIOS!A:A,"")} -> S02 | B5: Inflable | C5: 45955 | D5: Castillo | E5: {=XLOOKUP($D:$D,LISTA_SERVICIOS,LISTA_PRECIOS,0)} -> 650 | F5: 0 | G5: 0 | H5: 0 | J5: =E5+F5-G5-H5 -> 650 | K5: Sebastián | L5: =E5+F5-G5 -> 650 | M5: =IF(C5="","",TEXT(C5,"mmmm")) -> octubre | N5: =IF(C5="","",YEAR(C5)) -> 2025
A6: {=XLOOKUP(B6,SERVICIOS!B:B,SERVICIOS!A:A,"")} -> S02 | B6: Inflable | C6: 45955 | D6: Obstaculos | E6: {=XLOOKUP($D:$D,LISTA_SERVICIOS,LISTA_PRECIOS,0)} -> 1000 | F6: 0 | G6: 0 | H6: 0 | J6: =E6+F6-G6-H6 -> 1000 | K6: Angel | L6: =E6+F6-G6 -> 1000 | M6: =IF(C6="","",TEXT(C6,"mmmm")) -> octubre | N6: =IF(C6="","",YEAR(C6)) -> 2025
A7: {=XLOOKUP(B7,SERVICIOS!B:B,SERVICIOS!A:A,"")} -> S02 | B7: Inflable | C7: 45955 | D7: Superheróes | E7: {=XLOOKUP($D:$D,LISTA_SERVICIOS,LISTA_PRECIOS,0)} -> 800 | F7: 0 | G7: 100 | H7: 210 | I7: Angel | J7: =E7+F7-G7-H7 -> 490 | K7: Sebastián | L7: =E7+F7-G7 -> 700 | M7: =IF(C7="","",TEXT(C7,"mmmm")) -> octubre | N7: =IF(C7="","",YEAR(C7)) -> 2025
A8: {=XLOOKUP(B8,SERVICIOS!B:B,SERVICIOS!A:A,"")} -> S02 | B8: Inflable | C8: 45955 | D8: Spiderman_cubo | E8: {=XLOOKUP($D:$D,LISTA_SERVICIOS,LISTA_PRECIOS,0)} -> 600 | F8: 0 | G8: 0 | H8: 0 | J8: =E8+F8-G8-H8 -> 600 | K8: Angel | L8: =E8+F8-G8 -> 600 | M8: =IF(C8="","",TEXT(C8,"mmmm")) -> octubre | N8: =IF(C8="","",YEAR(C8)) -> 2025
A9: {=XLOOKUP(B9,SERVICIOS!B:B,SERVICIOS!A:A,"")} -> S02 | B9: Inflable | C9: 45955 | D9: Spiderman_circular | E9: {=XLOOKUP($D:$D,LISTA_SERVICIOS,LISTA_PRECIOS,0)} -> 800 | F9: 100 | G9: 0 | H9: 0 | J9: =E9+F9-G9-H9 -> 900 | K9: Angel | L9: =E9+F9-G9 -> 900 | M9: =IF(C9="","",TEXT(C9,"mmmm")) -> octubre | N9: =IF(C9="","",YEAR(C9)) -> 2025
A10: {=XLOOKUP(B10,SERVICIOS!B:B,SERVICIOS!A:A,"")} -> S02 | B10: Inflable | C10: 45955 | D10: Mickey | E10: {=XLOOKUP($D:$D,LISTA_SERVICIOS,LISTA_PRECIOS,0)} -> 600 | F10: 0 | G10: 0 | H10: 0 | J10: =E10+F10-G10-H10 -> 600 | K10: Angel | L10: =E10+F10-G10 -> 600 | M10: =IF(C10="","",TEXT(C10,"mmmm")) -> octubre | N10: =IF(C10="","",YEAR(C10)) -> 2025
A11: {=XLOOKUP(B11,SERVICIOS!B:B,SERVICIOS!A:A,"")} -> S03 | B11: Sonido | C11: 45955 | D11: Diamante | E11: {=XLOOKUP($D:$D,LISTA_SERVICIOS,LISTA_PRECIOS,0)} -> 6000 | F11: 3000 | G11: 0 | H11: 1500 | I11: Carlos | J11: =E11+F11-G11-H11 -> 7500 | K11: Carlos | L11: =E11+F11-G11 -> 9000 | M11: =IF(C11="","",TEXT(C11,"mmmm")) -> octubre | N11: =IF(C11="","",YEAR(C11)) -> 2025
A12: {=XLOOKUP(B12,SERVICIOS!B:B,SERVICIOS!A:A,"")} -> S01 | B12: Toro | C12: 45955 | D12: 2 horas toro | E12: {=XLOOKUP($D:$D,LISTA_SERVICIOS,LISTA_PRECIOS,0)} -> 2200 | F12: 0 | G12: 200 | H12: 600 | I12: Angel | J12: =E12+F12-G12-H12 -> 1400 | K12: Sebastián | L12: =E12+F12-G12 -> 2000 | M12: =IF(C12="","",TEXT(C12,"mmmm")) -> octubre | N12: =IF(C12="","",YEAR(C12)) -> 2025
A13: {=XLOOKUP(B13,SERVICIOS!B:B,SERVICIOS!A:A,"")} -> S01 | B13: Toro | C13: 45955 | D13: 1 hora toro | E13: {=XLOOKUP($D:$D,LISTA_SERVICIOS,LISTA_PRECIOS,0)} -> 1300 | F13: 0 | G13: 500 | H13: 800 | I13: Angel | J13: =E13+F13-G13-H13 -> 0 | L13: =E13+F13-G13 -> 800 | M13: =IF(C13="","",TEXT(C13,"mmmm")) -> octubre | N13: =IF(C13="","",YEAR(C13)) -> 2025
A14: {=XLOOKUP(B14,SERVICIOS!B:B,SERVICIOS!A:A,"")} -> S01 | B14: Toro | C14: 45955 | D14: 3 horas toro | E14: {=XLOOKUP($D:$D,LISTA_SERVICIOS,LISTA_PRECIOS,0)} -> 2600 | F14: 0 | G14: 0 | H14: 0 | J14: =E14+F14-G14-H14 -> 2600 | K14: Angel | L14: =E14+F14-G14 -> 2600 | M14: =IF(C14="","",TEXT(C14,"mmmm")) -> octubre | N14: =IF(C14="","",YEAR(C14)) -> 2025
A15: {=XLOOKUP(B15,SERVICIOS!B:B,SERVICIOS!A:A,"")} -> S01 | B15: Toro | C15: 45955 | D15: 2 horas toro | E15: {=XLOOKUP($D:$D,LISTA_SERVICIOS,LISTA_PRECIOS,0)} -> 2200 | F15: 0 | G15: 200 | H15: 600 | I15: Angel | J15: =E15+F15-G15-H15 -> 1400 | K15: Sebastián | L15: =E15+F15-G15 -> 2000 | M15: =IF(C15="","",TEXT(C15,"mmmm")) -> octubre | N15: =IF(C15="","",YEAR(C15)) -> 2025
A16: {=XLOOKUP(B16,SERVICIOS!B:B,SERVICIOS!A:A,"")} -> S03 | B16: Sonido | C16: 45955 | D16: Party | E16: {=XLOOKUP($D:$D,LISTA_SERVICIOS,LISTA_PRECIOS,0)} -> 2800 | F16: 0 | G16: 400 | H16: 0 | J16: =E16+F16-G16-H16 -> 2400 | K16: Sebastián | L16: =E16+F16-G16 -> 2400 | M16: =IF(C16="","",TEXT(C16,"mmmm")) -> octubre | N16: =IF(C16="","",YEAR(C16)) -> 2025
A17: {=XLOOKUP(B17,SERVICIOS!B:B,SERVICIOS!A:A,"")} -> S02 | B17: Inflable | C17: 45956 | D17: Princesas_circular | E17: {=XLOOKUP($D:$D,LISTA_SERVICIOS,LISTA_PRECIOS,0)} -> 800 | F17: 0 | G17: 0 | H17: 0 | J17: =E17+F17-G17-H17 -> 800 | K17: Sebastián | L17: =E17+F17-G17 -> 800 | M17: =IF(C17="","",TEXT(C17,"mmmm")) -> octubre | N17: =IF(C17="","",YEAR(C17)) -> 2025
A18: {=XLOOKUP(B18,SERVICIOS!B:B,SERVICIOS!A:A,"")} -> S02 | B18: Inflable | C18: 45956 | D18: Obstaculos | E18: {=XLOOKUP($D:$D,LISTA_SERVICIOS,LISTA_PRECIOS,0)} -> 1000 | F18: 0 | G18: 0 | H18: 0 | J18: =E18+F18-G18-H18 -> 1000 | K18: Sebastián | L18: =E18+F18-G18 -> 1000 | M18: =IF(C18="","",TEXT(C18,"mmmm")) -> octubre | N18: =IF(C18="","",YEAR(C18)) -> 2025
A19: {=XLOOKUP(B19,SERVICIOS!B:B,SERVICIOS!A:A,"")} -> S01 | B19: Toro | C19: 45956 | D19: 4 horas toro | E19: {=XLOOKUP($D:$D,LISTA_SERVICIOS,LISTA_PRECIOS,0)} -> 3000 | F19: 0 | G19: 200 | H19: 1500 | I19: Angel | J19: =E19+F19-G19-H19 -> 1300 | K19: Sebastián | L19: =E19+F19-G19 -> 2800 | M19: =IF(C19="","",TEXT(C19,"mmmm")) -> octubre | N19: =IF(C19="","",YEAR(C19)) -> 2025
A20: {=XLOOKUP(B20,SERVICIOS!B:B,SERVICIOS!A:A,"")} -> S02 | B20: Inflable | C20: 45956 | D20: Barbie | E20: {=XLOOKUP($D:$D,LISTA_SERVICIOS,LISTA_PRECIOS,0)} -> 800 | F20: 150 | G20: 0 | H20: 300 | I20: Angel | J20: =E20+F20-G20-H20 -> 650 | K20: Sebastián | L20: =E20+F20-G20 -> 950 | M20: =IF(C20="","",TEXT(C20,"mmmm")) -> octubre | N20: =IF(C20="","",YEAR(C20)) -> 2025
A21: {=XLOOKUP(B21,SERVICIOS!B:B,SERVICIOS!A:A,"")} -> S02 | B21: Inflable | C21: 45956 | D21: Mickey | E21: {=XLOOKUP($D:$D,LISTA_SERVICIOS,LISTA_PRECIOS,0)} -> 600 | F21: 0 | G21: 0 | H21: 0 | J21: =E21+F21-G21-H21 -> 600 | K21: Sebastián | L21: =E21+F21-G21 -> 600 | M21: =IF(C21="","",TEXT(C21,"mmmm")) -> octubre | N21: =IF(C21="","",YEAR(C21)) -> 2025
A22: {=XLOOKUP(B22,SERVICIOS!B:B,SERVICIOS!A:A,"")} -> S01 | B22: Toro | C22: 45956 | D22: 2 horas toro | E22: {=XLOOKUP($D:$D,LISTA_SERVICIOS,LISTA_PRECIOS,0)} -> 2200 | F22: 0 | G22: 300 | H22: 300 | I22: Angel | J22: =E22+F22-G22-H22 -> 1600 | K22: Sebastián | L22: =E22+F22-G22 -> 1900 | M22: =IF(C22="","",TEXT(C22,"mmmm")) -> octubre | N22: =IF(C22="","",YEAR(C22)) -> 2025
A23: {=XLOOKUP(B23,SERVICIOS!B:B,SERVICIOS!A:A,"")} -> S02 | B23: Inflable | C23: 45956 | D23: Princesas | E23: {=XLOOKUP($D:$D,LISTA_SERVICIOS,LISTA_PRECIOS,0)} -> 650 | F23: 0 | G23: 50 | H23: 200 | I23: Angel | J23: =E23+F23-G23-H23 -> 400 | K23: Sebastián | L23: =E23+F23-G23 -> 600 | M23: =IF(C23="","",TEXT(C23,"mmmm")) -> octubre | N23: =IF(C23="","",YEAR(C23)) -> 2025
A24: {=XLOOKUP(B24,SERVICIOS!B:B,SERVICIOS!A:A,"")} -> S02 | B24: Inflable | C24: 45957 | D24: Spiderman_circular | E24: {=XLOOKUP($D:$D,LISTA_SERVICIOS,LISTA_PRECIOS,0)} -> 800 | F24: 150 | G24: 0 | H24: 350 | I24: Angel | J24: =E24+F24-G24-H24 -> 600 | K24: Carlos | L24: =E24+F24-G24 -> 950 | M24: =IF(C24="","",TEXT(C24,"mmmm")) -> octubre | N24: =IF(C24="","",YEAR(C24)) -> 2025
A25: {=XLOOKUP(B25,SERVICIOS!B:B,SERVICIOS!A:A,"")} -> S03 | B25: sonido | C25: 45961 | D25: Deluxe | E25: {=XLOOKUP($D:$D,LISTA_SERVICIOS,LISTA_PRECIOS,0)} -> 4000 | F25: 500 | G25: 0 | H25: 0 | J25: =E25+F25-G25-H25 -> 4500 | K25: Angel | L25: =E25+F25-G25 -> 4500 | M25: =IF(C25="","",TEXT(C25,"mmmm")) -> octubre | N25: =IF(C25="","",YEAR(C25)) -> 2025
A26: {=XLOOKUP(B26,SERVICIOS!B:B,SERVICIOS!A:A,"")} -> S03 | B26: sonido | C26: 45961 | D26: Premium | E26: {=XLOOKUP($D:$D,LISTA_SERVICIOS,LISTA_PRECIOS,0)} -> 4700 | F26: 0 | G26: 200 | H26: 0 | J26: =E26+F26-G26-H26 -> 4500 | K26: Carlos | L26: =E26+F26-G26 -> 4500 | M26: =IF(C26="","",TEXT(C26,"mmmm")) -> octubre | N26: =IF(C26="","",YEAR(C26)) -> 2025
A27: {=XLOOKUP(B27,SERVICIOS!B:B,SERVICIOS!A:A,"")} -> S01 | B27: Toro | C27: 45961 | D27: 2 horas toro | E27: {=XLOOKUP($D:$D,LISTA_SERVICIOS,LISTA_PRECIOS,0)} -> 2200 | F27: 0 | G27: 200 | H27: 0 | J27: =E27+F27-G27-H27 -> 2000 | K27: Angel | L27: =E27+F27-G27 -> 2000 | M27: =IF(C27="","",TEXT(C27,"mmmm")) -> octubre | N27: =IF(C27="","",YEAR(C27)) -> 2025
A28: {=XLOOKUP(B28,SERVICIOS!B:B,SERVICIOS!A:A,"")} -> S02 | B28: Inflable | C28: 45962 | D28: Spiderman_circular | E28: {=XLOOKUP($D:$D,LISTA_SERVICIOS,LISTA_PRECIOS,0)} -> 800 | F28: 0 | G28: 0 | H28: 0 | J28: =E28+F28-G28-H28 -> 800 | K28: Carlos | L28: =E28+F28-G28 -> 800 | M28: =IF(C28="","",TEXT(C28,"mmmm")) -> noviembre | N28: =IF(C28="","",YEAR(C28)) -> 2025
A29: {=XLOOKUP(B29,SERVICIOS!B:B,SERVICIOS!A:A,"")} -> S02 | B29: Inflable | C29: 45962 | D29: Castillo | E29: {=XLOOKUP($D:$D,LISTA_SERVICIOS,LISTA_PRECIOS,0)} -> 650 | F29: 0 | G29: 0 | H29: 0 | J29: =E29+F29-G29-H29 -> 650 | K29: Angel | L29: =E29+F29-G29 -> 650 | M29: =IF(C29="","",TEXT(C29,"mmmm")) -> noviembre | N29: =IF(C29="","",YEAR(C29)) -> 2025
A30: {=XLOOKUP(B30,SERVICIOS!B:B,SERVICIOS!A:A,"")} -> S02 | B30: Inflable | C30: 45962 | D30: Superheróes | E30: {=XLOOKUP($D:$D,LISTA_SERVICIOS,LISTA_PRECIOS,0)} -> 800 | F30: 0 | G30: 0 | H30: 0 | J30: =E30+F30-G30-H30 -> 800 | K30: Angel | L30: =E30+F30-G30 -> 800 | M30: =IF(C30="","",TEXT(C30,"mmmm")) -> noviembre | N30: =IF(C30="","",YEAR(C30)) -> 2025
A31: {=XLOOKUP(B31,SERVICIOS!B:B,SERVICIOS!A:A,"")} -> S01 | B31: Toro | C31: 45962 | D31: 1 hora toro | E31: {=XLOOKUP($D:$D,LISTA_SERVICIOS,LISTA_PRECIOS,0)} -> 1300 | F31: 0 | G31: 0 | H31: 0 | J31: =E31+F31-G31-H31 -> 1300 | K31: Sebastián | L31: =E31+F31-G31 -> 1300 | M31: =IF(C31="","",TEXT(C31,"mmmm")) -> noviembre | N31: =IF(C31="","",YEAR(C31)) -> 2025
A32: {=XLOOKUP(B32,SERVICIOS!B:B,SERVICIOS!A:A,"")} -> S02 | B32: Inflable | C32: 45962 | D32: Princesas_circular | E32: {=XLOOKUP($D:$D,LISTA_SERVICIOS,LISTA_PRECIOS,0)} -> 800 | F32: 0 | G32: 0 | H32: 0 | J32: =E32+F32-G32-H32 -> 800 | K32: Angel | L32: =E32+F32-G32 -> 800 | M32: =IF(C32="","",TEXT(C32,"mmmm")) -> noviembre | N32: =IF(C32="","",YEAR(C32)) -> 2025
A33: {=XLOOKUP(B33,SERVICIOS!B:B,SERVICIOS!A:A,"")} -> S01 | B33: Toro | C33: 45968 | D33: 1 hora toro | E33: {=XLOOKUP($D:$D,LISTA_SERVICIOS,LISTA_PRECIOS,0)} -> 1300 | F33: 0 | G33: 580 | H33: 720 | I33: Angel | J33: =E33+F33-G33-H33 -> 0 | L33: =E33+F33-G33 -> 720 | M33: =IF(C33="","",TEXT(C33,"mmmm")) -> noviembre | N33: =IF(C33="","",YEAR(C33)) -> 2025
A34: {=XLOOKUP(B34,SERVICIOS!B:B,SERVICIOS!A:A,"")} -> S03 | B34: Sonido | C34: 45969 | D34: Diamante | E34: {=XLOOKUP($D:$D,LISTA_SERVICIOS,LISTA_PRECIOS,0)} -> 6000 | F34: 0 | G34: 0 | H34: 0 | J34: =E34+F34-G34-H34 -> 6000 | K34: Angel | L34: =E34+F34-G34 -> 6000 | M34: =IF(C34="","",TEXT(C34,"mmmm")) -> noviembre | N34: =IF(C34="","",YEAR(C34)) -> 2025
A35: {=XLOOKUP(B35,SERVICIOS!B:B,SERVICIOS!A:A,"")} -> S04 | B35: Pista | C35: 45969 | D35: 5x4 | E35: {=XLOOKUP($D:$D,LISTA_SERVICIOS,LISTA_PRECIOS,0)} -> 5000 | F35: 0 | G35: 0 | H35: 0 | J35: =E35+F35-G35-H35 -> 5000 | K35: Angel | L35: =E35+F35-G35 -> 5000 | M35: =IF(C35="","",TEXT(C35,"mmmm")) -> noviembre | N35: =IF(C35="","",YEAR(C35)) -> 2025
A36: {=XLOOKUP(B36,SERVICIOS!B:B,SERVICIOS!A:A,"")} -> S02 | B36: Inflable | C36: 45969 | D36: Obstaculos | E36: {=XLOOKUP($D:$D,LISTA_SERVICIOS,LISTA_PRECIOS,0)} -> 1000 | F36: 600 | G36: 0 | H36: 0 | J36: =E36+F36-G36-H36 -> 1600 | K36: Angel | L36: =E36+F36-G36 -> 1600 | M36: =IF(C36="","",TEXT(C36,"mmmm")) -> noviembre | N36: =IF(C36="","",YEAR(C36)) -> 2025
A37: {=XLOOKUP(B37,SERVICIOS!B:B,SERVICIOS!A:A,"")} -> S02 | B37: Inflable | C37: 45969 | D37: Spiderman_cubo | E37: {=XLOOKUP($D:$D,LISTA_SERVICIOS,LISTA_PRECIOS,0)} -> 600 | F37: 0 | G37: 0 | H37: 0 | J37: =E37+F37-G37-H37 -> 600 | K37: Angel | L37: =E37+F37-G37 -> 600 | M37: =IF(C37="","",TEXT(C37,"mmmm")) -> noviembre | N37: =IF(C37="","",YEAR(C37)) -> 2025
A38: {=XLOOKUP(B38,SERVICIOS!B:B,SERVICIOS!A:A,"")} -> S02 | B38: Inflable | C38: 45969 | D38: Spiderman_circular | E38: {=XLOOKUP($D:$D,LISTA_SERVICIOS,LISTA_PRECIOS,0)} -> 800 | F38: 0 | G38: 0 | H38: 0 | J38: =E38+F38-G38-H38 -> 800 | K38: Angel | L38: =E38+F38-G38 -> 800 | M38: =IF(C38="","",TEXT(C38,"mmmm")) -> noviembre | N38: =IF(C38="","",YEAR(C38)) -> 2025
A39: {=XLOOKUP(B39,SERVICIOS!B:B,SERVICIOS!A:A,"")} -> S02 | B39: Inflable | C39: 45969 | D39: Superheróes | E39: {=XLOOKUP($D:$D,LISTA_SERVICIOS,LISTA_PRECIOS,0)} -> 800 | F39: 0 | G39: 100 | H39: 0 | J39: =E39+F39-G39-H39 -> 700 | K39: Angel | L39: =E39+F39-G39 -> 700 | M39: =IF(C39="","",TEXT(C39,"mmmm")) -> noviembre | N39: =IF(C39="","",YEAR(C39)) -> 2025
A40: {=XLOOKUP(B40,SERVICIOS!B:B,SERVICIOS!A:A,"")} -> S01 | B40: Toro | C40: 45969 | D40: 3 horas toro | E40: {=XLOOKUP($D:$D,LISTA_SERVICIOS,LISTA_PRECIOS,0)} -> 2600 | F40: 0 | G40: 200 | H40: 0 | J40: =E40+F40-G40-H40 -> 2400 | K40: Angel | L40: =E40+F40-G40 -> 2400 | M40: =IF(C40="","",TEXT(C40,"mmmm")) -> noviembre | N40: =IF(C40="","",YEAR(C40)) -> 2025
...

Sheet SALARIOS
A1: Fecha | B1: Trabajador | C1: Servicio | D1: descripción | E1: Monto | F1: Descuento | G1: Aumento | H1: Total | I1: Mes | J1: Año
A2: 45956 | B2: Angel | C2: Bono | D2: Bono semanal | E2: {=XLOOKUP($D2,concepto_salarios,monto_salarios,0)} -> 100 | F2: 0 | G2: 0 | H2: =E2-F2+G2 -> 100 | I2: =IF(A2="","",TEXT(A2,"mmmm")) -> octubre | J2: =IF(A2="","",YEAR(A2)) -> 2025
A3: 45956 | B3: Jesualdo | C3: Inflable | D3: Princesas dejar y recoger | E3: {=XLOOKUP($D3,concepto_salarios,monto_salarios,0)} -> 90 | F3: 0 | G3: 0 | H3: =E3-F3+G3 -> 90 | I3: =IF(A3="","",TEXT(A3,"mmmm")) -> octubre | J3: =IF(A3="","",YEAR(A3)) -> 2025
A4: 45956 | B4: Jesualdo | C4: Inflable | D4: Mickey dejar y recoger | E4: {=XLOOKUP($D4,concepto_salarios,monto_salarios,0)} -> 90 | F4: 0 | G4: 0 | H4: =E4-F4+G4 -> 90 | I4: =IF(A4="","",TEXT(A4,"mmmm")) -> octubre | J4: =IF(A4="","",YEAR(A4)) -> 2025
A5: 45956 | B5: Jesualdo | C5: Inflable | D5: Barbie dejar y recoger | E5: {=XLOOKUP($D5,concepto_salarios,monto_salarios,0)} -> 100 | F5: 0 | G5: 0 | H5: =E5-F5+G5 -> 100 | I5: =IF(A5="","",TEXT(A5,"mmmm")) -> octubre | J5: =IF(A5="","",YEAR(A5)) -> 2025
A6: 45956 | B6: Jesualdo | C6: Inflable | D6: 2 horas toro | E6: {=XLOOKUP($D6,concepto_salarios,monto_salarios,0)} -> 250 | F6: 0 | G6: 0 | H6: =E6-F6+G6 -> 250 | I6: =IF(A6="","",TEXT(A6,"mmmm")) -> octubre | J6: =IF(A6="","",YEAR(A6)) -> 2025
A7: 45956 | B7: Juan | C7: Inflable | D7: Princesas dejar y recoger | E7: {=XLOOKUP($D7,concepto_salarios,monto_salarios,0)} -> 90 | F7: 0 | G7: 0 | H7: =E7-F7+G7 -> 90 | I7: =IF(A7="","",TEXT(A7,"mmmm")) -> octubre | J7: =IF(A7="","",YEAR(A7)) -> 2025
A8: 45956 | B8: Juan | C8: Inflable | D8: Mickey dejar y recoger | E8: {=XLOOKUP($D8,concepto_salarios,monto_salarios,0)} -> 90 | F8: 0 | G8: 0 | H8: =E8-F8+G8 -> 90 | I8: =IF(A8="","",TEXT(A8,"mmmm")) -> octubre | J8: =IF(A8="","",YEAR(A8)) -> 2025
A9: 45956 | B9: Juan | C9: Inflable | D9: Barbie dejar y recoger | E9: {=XLOOKUP($D9,concepto_salarios,monto_salarios,0)} -> 100 | F9: 0 | G9: 0 | H9: =E9-F9+G9 -> 100 | I9: =IF(A9="","",TEXT(A9,"mmmm")) -> octubre | J9: =IF(A9="","",YEAR(A9)) -> 2025
A10: 45956 | B10: Juan | C10: Toro | D10: 2 horas toro | E10: {=XLOOKUP($D10,concepto_salarios,monto_salarios,0)} -> 250 | F10: 0 | G10: 0 | H10: =E10-F10+G10 -> 250 | I10: =IF(A10="","",TEXT(A10,"mmmm")) -> octubre | J10: =IF(A10="","",YEAR(A10)) -> 2025
A11: 45956 | B11: Marco | C11: Inflable | D11: Obstaculos recoger | E11: {=XLOOKUP($D11,concepto_salarios,monto_salarios,0)} -> 75 | F11: 0 | G11: 0 | H11: =E11-F11+G11 -> 75 | I11: =IF(A11="","",TEXT(A11,"mmmm")) -> octubre | J11: =IF(A11="","",YEAR(A11)) -> 2025
A12: 45956 | B12: Marco | C12: Inflable | D12: Princesas c dejar y recoger | E12: {=XLOOKUP($D12,concepto_salarios,monto_salarios,0)} -> 100 | F12: 0 | G12: 0 | H12: =E12-F12+G12 -> 100 | I12: =IF(A12="","",TEXT(A12,"mmmm")) -> octubre | J12: =IF(A12="","",YEAR(A12)) -> 2025
A13: 45956 | B13: Marco | C13: Inflable | D13: Obstaculos dejar y recoger | E13: {=XLOOKUP($D13,concepto_salarios,monto_salarios,0)} -> 150 | F13: 0 | G13: 0 | H13: =E13-F13+G13 -> 150 | I13: =IF(A13="","",TEXT(A13,"mmmm")) -> octubre | J13: =IF(A13="","",YEAR(A13)) -> 2025
... A68: 45970 | B68: Juan | C68: Inflable | D68: Mickey dejar y recoger | E68: {=XLOOKUP($D68,concepto_salarios,monto_salarios,0)} -> 90 | F68: 0 | G68: 0 | H68: =E68-F68+G68 -> 90 | I68: =IF(A68="","",TEXT(A68,"mmmm")) -> noviembre | J68: =IF(A68="","",YEAR(A68)) -> 2025
A69: 45970 | B69: Juan | C69: Bono | D69: Gastos extra | E69: 100 | F69: 0 | G69: 0 | H69: =E69-F69+G69 -> 100 | I69: =IF(A69="","",TEXT(A69,"mmmm")) -> noviembre | J69: =IF(A69="","",YEAR(A69)) -> 2025
A70: 45970 | B70: Juan | C70: Inflable | D70: Obstaculos dejar | E70: {=XLOOKUP($D70,concepto_salarios,monto_salarios,0)} -> 75 | F70: 0 | G70: 0 | H70: =E70-F70+G70 -> 75 | I70: =IF(A70="","",TEXT(A70,"mmmm")) -> noviembre | J70: =IF(A70="","",YEAR(A70)) -> 2025
A71: 45970 | B71: Juan | C71: Inflable | D71: Spiderman c recoger | E71: {=XLOOKUP($D71,concepto_salarios,monto_salarios,0)} -> 50 | F71: 0 | G71: 0 | H71: =E71-F71+G71 -> 50 | I71: =IF(A71="","",TEXT(A71,"mmmm")) -> noviembre | J71: =IF(A71="","",YEAR(A71)) -> 2025
A72: 45970 | B72: Juan | C72: Inflable | D72: Spiderman cubo recoger | E72: {=XLOOKUP($D72,concepto_salarios,monto_salarios,0)} -> 45 | F72: 0 | G72: 0 | H72: =E72-F72+G72 -> 45 | I72: =IF(A72="","",TEXT(A72,"mmmm")) -> noviembre | J72: =IF(A72="","",YEAR(A72)) -> 2025
A73: 45970 | B73: Juan | C73: Toro | D73: 2 horas toro | E73: {=XLOOKUP($D73,concepto_salarios,monto_salarios,0)} -> 250 | F73: 0 | G73: 0 | H73: =E73-F73+G73 -> 250 | I73: =IF(A73="","",TEXT(A73,"mmmm")) -> noviembre | J73: =IF(A73="","",YEAR(A73)) -> 2025
A74: 45970 | B74: Marco | C74: Toro | D74: 2 horas toro | E74: {=XLOOKUP($D74,concepto_salarios,monto_salarios,0)} -> 250 | F74: 0 | G74: 0 | H74: =E74-F74+G74 -> 250 | I74: =IF(A74="","",TEXT(A74,"mmmm")) -> noviembre | J74: =IF(A74="","",YEAR(A74)) -> 2025
A75: 45970 | B75: Marco | C75: Inflable | D75: Princesas c dejar y recoger | E75: {=XLOOKUP($D75,concepto_salarios,monto_salarios,0)} -> 100 | F75: 0 | G75: 0 | H75: =E75-F75+G75 -> 100 | I75: =IF(A75="","",TEXT(A75,"mmmm")) -> noviembre | J75: =IF(A75="","",YEAR(A75)) -> 2025
A76: 45970 | B76: Marco | C76: Inflable | D76: Mickey dejar y recoger | E76: {=XLOOKUP($D76,concepto_salarios,monto_salarios,0)} -> 90 | F76: 0 | G76: 0 | H76: =E76-F76+G76 -> 90 | I76: =IF(A76="","",TEXT(A76,"mmmm")) -> noviembre | J76: =IF(A76="","",YEAR(A76)) -> 2025
A77: 45970 | B77: Marco | C77: Bono | D77: Gastos extra | E77: 100 | F77: 0 | G77: 0 | H77: =E77-F77+G77 -> 100 | I77: =IF(A77="","",TEXT(A77,"mmmm")) -> noviembre | J77: =IF(A77="","",YEAR(A77)) -> 2025
A78: 45970 | B78: Sebastián | C78: Inflable | D78: Princesas solo | E78: {=XLOOKUP($D78,concepto_salarios,monto_salarios,0)} -> 90 | F78: 0 | G78: 0 | H78: =E78-F78+G78 -> 90 | I78: =IF(A78="","",TEXT(A78,"mmmm")) -> noviembre | J78: =IF(A78="","",YEAR(A78)) -> 2025
A79: 45975 | B79: Alejandro | C79: Sonido | D79: Instalar sonido grande | E79: {=XLOOKUP($D79,concepto_salarios,monto_salarios,0)} -> 150 | F79: 0 | G79: 50 | H79: =E79-F79+G79 -> 200 | I79: =IF(A79="","",TEXT(A79,"mmmm")) -> noviembre | J79: =IF(A79="","",YEAR(A79)) -> 2025
A80: 45975 | B80: Alejandro | C80: Bono | D80: Bono noche | E80: {=XLOOKUP($D80,concepto_salarios,monto_salarios,0)} -> 100 | F80: 0 | G80: 0 | H80: =E80-F80+G80 -> 100 | I80: =IF(A80="","",TEXT(A80,"mmmm")) -> noviembre | J80: =IF(A80="","",YEAR(A80)) -> 2025
A81: 45975 | B81: Carlos | C81: Sonido | D81: Instalar sonido grande | E81: {=XLOOKUP($D81,concepto_salarios,monto_salarios,0)} -> 150 | F81: 0 | G81: 50 | H81: =E81-F81+G81 -> 200 | I81: =IF(A81="","",TEXT(A81,"mmmm")) -> noviembre | J81: =IF(A81="","",YEAR(A81)) -> 2025
A82: 45975 | B82: Carlos | C82: Bono | D82: Bono noche | E82: {=XLOOKUP($D82,concepto_salarios,monto_salarios,0)} -> 100 | F82: 0 | G82: 0 | H82: =E82-F82+G82 -> 100 | I82: =IF(A82="","",TEXT(A82,"mmmm")) -> noviembre | J82: =IF(A82="","",YEAR(A82)) -> 2025
A83: 45976 | B83: Angel | C83: Inflable | D83: Minions dejar y recoger | E83: {=XLOOKUP($D83,concepto_salarios,monto_salarios,0)} -> 100 | F83: 0 | G83: 0 | H83: =E83-F83+G83 -> 100 | I83: =IF(A83="","",TEXT(A83,"mmmm")) -> noviembre | J83: =IF(A83="","",YEAR(A83)) -> 2025
A84: 45976 | B84: Angel | C84: Toro | D84: 2 horas toro | E84: {=XLOOKUP($D84,concepto_salarios,monto_salarios,0)} -> 250 | F84: 0 | G84: 0 | H84: =E84-F84+G84 -> 250 | I84: =IF(A84="","",TEXT(A84,"mmmm")) -> noviembre | J84: =IF(A84="","",YEAR(A84)) -> 2025
A85: 45976 | B85: Angel | C85: Toro | D85: Instalar y recoger toro | E85: {=XLOOKUP($D85,concepto_salarios,monto_salarios,0)} -> 200 | F85: 0 | G85: 0 | H85: =E85-F85+G85 -> 200 | I85: =IF(A85="","",TEXT(A85,"mmmm")) -> noviembre | J85: =IF(A85="","",YEAR(A85)) -> 2025
A86: 45976 | B86: Angel | C86: Toro | D86: Instalar toro | E86: {=XLOOKUP($D86,concepto_salarios,monto_salarios,0)} -> 100 | F86: 0 | G86: 0 | H86: =E86-F86+G86 -> 100 | I86: =IF(A86="","",TEXT(A86,"mmmm")) -> noviembre | J86: =IF(A86="","",YEAR(A86)) -> 2025
A87: 45976 | B87: Angel | C87: Inflable | D87: Castillo dejar | E87: {=XLOOKUP($D87,concepto_salarios,monto_salarios,0)} -> 50 | F87: 0 | G87: 0 | H87: =E87-F87+G87 -> 50 | I87: =IF(A87="","",TEXT(A87,"mmmm")) -> noviembre | J87: =IF(A87="","",YEAR(A87)) -> 2025
A88: 45976 | B88: Axel | C88: Toro | D88: Instalar toro | E88: {=XLOOKUP($D88,concepto_salarios,monto_salarios,0)} -> 100 | F88: 0 | G88: 0 | H88: =E88-F88+G88 -> 100 | I88: =IF(A88="","",TEXT(A88,"mmmm")) -> noviembre | J88: =IF(A88="","",YEAR(A88)) -> 2025
A89: 45976 | B89: Axel | C89: Toro | D89: 3 horas toro | E89: {=XLOOKUP($D89,concepto_salarios,monto_salarios,0)} -> 350 | F89: 0 | G89: 0 | H89: =E89-F89+G89 -> 350 | I89: =IF(A89="","",TEXT(A89,"mmmm")) -> noviembre | J89: =IF(A89="","",YEAR(A89)) -> 2025
... A235: 45997 | B235: Ricardo | C235: Toro | D235: 2 horas toro | E235: {=XLOOKUP($D235,concepto_salarios,monto_salarios,0)} -> 250 | F235: 0 | G235: 0 | H235: =E235-F235+G235 -> 250 | I235: =IF(A235="","",TEXT(A235,"mmmm")) -> diciembre | J235: =IF(A235="","",YEAR(A235)) -> 2025
A236: 45997 | B236: Ricardo | C236: Bono | D236: Gastos extra | E236: 100 | F236: 0 | G236: 0 | H236: =E236-F236+G236 -> 100 | I236: =IF(A236="","",TEXT(A236,"mmmm")) -> diciembre | J236: =IF(A236="","",YEAR(A236)) -> 2025
A237: 45997 | B237: Rodrigo | C237: Sonido | D237: Diamante animador | E237: {=XLOOKUP($D237,concepto_salarios,monto_salarios,0)} -> 870 | F237: 225 | G237: 0 | H237: =E237-F237+G237 -> 645 | I237: =IF(A237="","",TEXT(A237,"mmmm")) -> diciembre | J237: =IF(A237="","",YEAR(A237)) -> 2025
A238: 45997 | B238: Sebastián | C238: Sonido | D238: Premium dj acompañado | E238: {=XLOOKUP($D238,concepto_salarios,monto_salarios,0)} -> 810 | F238: 84 | G238: 0 | H238: =E238-F238+G238 -> 726 | I238: =IF(A238="","",TEXT(A238,"mmmm")) -> diciembre | J238: =IF(A238="","",YEAR(A238)) -> 2025
A239: 45997 | B239: Sebastián | C239: Bono | D239: Bono noche | E239: {=XLOOKUP($D239,concepto_salarios,monto_salarios,0)} -> 100 | F239: 0 | G239: 0 | H239: =E239-F239+G239 -> 100 | I239: =IF(A239="","",TEXT(A239,"mmmm")) -> diciembre | J239: =IF(A239="","",YEAR(A239)) -> 2025
...

Sheet GASTOS
A1: FECHA | B1: CONCEPTO | C1: MONTO | D1: SOCIO | E1: Mes | F1: Año | G1: Columna 1
A2: 45955 | B2: Gasolina faw | C2: 200 | D2: Angel | E2: =IF(A2="","",TEXT(A2,"mmmm")) -> octubre | F2: =IF(A2="","",YEAR(A2)) -> 2025 | G2: Gasolina
A3: 45955 | B3: Cinta gris | C3: 169 | D3: Angel | E3: =IF(A3="","",TEXT(A3,"mmmm")) -> octubre | F3: =IF(A3="","",YEAR(A3)) -> 2025 | G3: Suministros audio
A4: 45955 | B4: Pilas y cable plug | C4: 637 | D4: Angel | E4: =IF(A4="","",TEXT(A4,"mmmm")) -> octubre | F4: =IF(A4="","",YEAR(A4)) -> 2025 | G4: Artículos de sonido
A5: 45955 | B5: Cables y switch | C5: 150 | D5: Angel | E5: =IF(A5="","",TEXT(A5,"mmmm")) -> octubre | F5: =IF(A5="","",YEAR(A5)) -> 2025 | G5: Artículos de reparación
A6: 45955 | B6: Cables y switch | C6: 282 | D6: Angel | E6: =IF(A6="","",TEXT(A6,"mmmm")) -> octubre | F6: =IF(A6="","",YEAR(A6)) -> 2025 | G6: Artículos de reparación
A7: 45955 | B7: Cables XLR | C7: 729 | D7: Angel | E7: =IF(A7="","",TEXT(A7,"mmmm")) -> octubre | F7: =IF(A7="","",YEAR(A7)) -> 2025 | G7: Artículos de sonido
A8: 45955 | B8: Gasolina Mazda | C8: 500 | D8: Angel | E8: =IF(A8="","",TEXT(A8,"mmmm")) -> octubre | F8: =IF(A8="","",YEAR(A8)) -> 2025 | G8: Gasolina
A9: 45955 | B9: Gasolina Ranger | C9: 200 | D9: Angel | E9: =IF(A9="","",TEXT(A9,"mmmm")) -> octubre | F9: =IF(A9="","",YEAR(A9)) -> 2025 | G9: Gasolina
A10: 45955 | B10: Cinta de aislar | C10: 25 | D10: Angel | E10: =IF(A10="","",TEXT(A10,"mmmm")) -> octubre | F10: =IF(A10="","",YEAR(A10)) -> 2025 | G10: Artículos de reparación
A11: 45955 | B11: Reparación bocinas | C11: 4100 | D11: Angel | E11: =IF(A11="","",TEXT(A11,"mmmm")) -> octubre | F11: =IF(A11="","",YEAR(A11)) -> 2025 | G11: Reparación audio
A12: 45955 | B12: Reparación Dino | C12: 500 | D12: Angel | E12: =IF(A12="","",TEXT(A12,"mmmm")) -> octubre | F12: =IF(A12="","",YEAR(A12)) -> 2025 | G12: Reparación Toros
A13: 45955 | B13: Renta audio | C13: 500 | D13: Angel | E13: =IF(A13="","",TEXT(A13,"mmmm")) -> octubre | F13: =IF(A13="","",YEAR(A13)) -> 2025 | G13: Renta Sonido
... A174: 46082 | B174: CHEQUEO MAZDA | C174: 50 | D174: Carlos | E174: =IF(A174="","",TEXT(A174,"mmmm")) -> marzo | F174: =IF(A174="","",YEAR(A174)) -> 2026 | G174: Suministros toro

Sheet Matriz antes
A1: FECHA | B1: 46073
P2: CUENTAS CON SEBAS
A3: INGRESOS | B3: CONCEPTO | C3: ANTICIPO | D3: RECIBIÓ ANTICIPO | E3: LIQUIDACIÓN | F3: RECIBIÓ LIQUIDACIÓN | H3: GASTOS | I3: CONCEPTO | J3: SOCIO | L3: Salario | M3: Concepto | N3: Trabajador | P3: INGRESOS | Q3: =SUM(INGRESOS_2[INGRESOS]) -> 700 | S3: GASTOS SEBAS | T3: =SUMIF(GASTOS_2[SOCIO],"Sebastián",GASTOS_2[GASTOS]) -> 0
A4: =IFERROR(__xludf.DUMMYFUNCTION("IFNA(FILTER(INGRESOS!L:L,INGRESOS!C:C=B1),0)"),700.0) -> 700 | B4: =IFERROR(__xludf.DUMMYFUNCTION("IFNA(FILTER(INGRESOS!D:D,INGRESOS!C:C=B1),""-"")"),"Party") -> Party | C4: =IFERROR(__xludf.DUMMYFUNCTION("IFNA(FILTER(INGRESOS!H:H,INGRESOS!C:C=B1),0)"),0.0) -> 0 | D4: =IFERROR(__xludf.DUMMYFUNCTION("IFNA(FILTER(INGRESOS!I:I,INGRESOS!C:C=B1),""-"")"),"") | E4: =IFERROR(__xludf.DUMMYFUNCTION("IFNA(FILTER(INGRESOS!J:J,INGRESOS!C:C=B1),0)"),700.0) -> 700 | F4: =IFERROR(__xludf.DUMMYFUNCTION("IFNA(FILTER(INGRESOS!K:K,INGRESOS!C:C=B1),""-"")"),"Sebastián") -> Sebastián | H4: =IFERROR(__xludf.DUMMYFUNCTION("IFNA(FILTER(GASTOS!C:C,GASTOS!A:A=B1),0)"),0.0) -> 0 | I4: =IFERROR(__xludf.DUMMYFUNCTION("IFNA(FILTER(GASTOS!B:B,GASTOS!A:A=B1),""-"")"),"-") -> - | J4: =IFERROR(__xludf.DUMMYFUNCTION("IFNA(FILTER(GASTOS!D:D,GASTOS!A:A=B1),""-"")"),"-") -> - | L4: =IFERROR(__xludf.DUMMYFUNCTION("ifna(FILTER(SALARIOS!H:H,SALARIOS!A:A=$B$1),0)"),50.0) -> 50 | M4: =IFERROR(__xludf.DUMMYFUNCTION("IFNA(FILTER(SALARIOS!D:D,SALARIOS!A:A=$B$1),""-"")"),"Instalar sonido") -> Instalar sonido | N4: =IFERROR(__xludf.DUMMYFUNCTION("IFNA(FILTER(SALARIOS!B:B,SALARIOS!A:A=$B$1),""-"")"),"Sebastián") -> Sebastián | P4: GASTOS | Q4: =SUM(GASTOS_2[GASTOS]) -> 0 | S4: GASTOS CARLOS | T4: =SUMIF(GASTOS_2[SOCIO],"Carlos",GASTOS_2[GASTOS]) -> 0
P5: SALARIOS | Q5: =SUM(SALARIOS_2[Salario]) -> 50 | S5: GASTOS ANGEL | T5: =SUMIF(GASTOS_2[SOCIO],"Angel",GASTOS_2[GASTOS]) -> 0
P6: EGRESOS | Q6: =Q4+Q5 -> 50 | S6: SALARIO SEBAS | T6: =SUMIF(SALARIOS_2[Trabajador],"Sebastián",SALARIOS_2[Salario]) -> 50
P7: UTILIDAD NETA | Q7: =Q3-Q6 -> 650 | S7: SALARIOS EXCEPTO SEBAS | T7: =Q5-T6 -> 0
P8: UTILIDAD SOCIO | Q8: =Q7/2 -> 325 | S8: INGRESOS SEBAS | T8: =SUMIF(INGRESOS_2[RECIBIÓ ANTICIPO],"Sebastián",INGRESOS_2[ANTICIPO])+SUMIF(INGRESOS_2[RECIBIÓ LIQUIDACIÓN],"Sebastián",INGRESOS_2[LIQUIDACIÓN]) -> 700
P9: SALDO AQUINO | Q9: =Q8+T6+T3-T8 -> -325 | S9: INGRESOS CARLOS | T9: =SUMIF(INGRESOS_2[RECIBIÓ ANTICIPO],"Carlos",INGRESOS_2[ANTICIPO])+SUMIF(INGRESOS_2[RECIBIÓ LIQUIDACIÓN],"Carlos",INGRESOS_2[LIQUIDACIÓN]) -> 0
P10: SALDO VASQUEZ | Q10: =Q8+T4+T5+T7-T9-T10 -> 325 | S10: INGRESOS ANGEL | T10: =SUMIF(INGRESOS_2[RECIBIÓ ANTICIPO],"Angel",INGRESOS_2[ANTICIPO])+SUMIF(INGRESOS_2[RECIBIÓ LIQUIDACIÓN],"Angel",INGRESOS_2[LIQUIDACIÓN]) -> 0
P11: MARGEN DE GANANCIA | Q11: =(Q7/Q3) -> 0.92857143 | S11: SALARIO ANGEL | T11: =SUMIF(SALARIOS_2[Trabajador],"Angel",SALARIOS_2[Salario]) -> 0
S12: SALARIO CARLOS | T12: =SUMIF(SALARIOS_2[Trabajador],"Carlos",SALARIOS_2[Salario]) -> 0
P15: CUENTAS CON CHARLY | S15: Java | T15: Sebas
P17: GANANCIAS | Q17: =Q8 -> 325 | S17: 209 | T17: 350
P18: GANANCIAS CADA QUIEN | Q18: =Q17/2 -> 162.5 | S18: 1540 | T18: 603
P19: TIENE CHARLY | Q19: =T9 -> 0 | S19: 3147 | T19: 225.5
P20: TIENE ANGEL | Q20: =T10+Q10 -> 325 | S20: =SUM(S17:S19) -> 4896 | T20: 1500 | V20: =S20-T22 -> -1927.5
P21: GASTOS CHARLY | Q21: =T4 -> 0 | T21: 4145
P22: GASTOS ANGEL | Q22: =T5 -> 0 | T22: =SUM(T17:T21) -> 6823.5
P23: PAGO DE SALARIOS | Q23: =T7-T11-T12 -> 0
P24: SALARIO CARLOS | Q24: =T12 -> 0
P25: SALARIO ANGEL | Q25: =T11 -> 0
P26: EXTRA ANGEL | Q26: 0
P27: EXTRA CHARLY | Q27: 0
P28: UTILIDAD CARLOS | Q28: =Q18+Q24+Q23+Q27+Q21-Q19 -> 162.5
P29: UTILIDAD ANGEL | Q29: =Q18+Q25+Q26+Q22-Q20 -> -162.5

Sheet Lista de gastos
A1: Concepto
A2: Artículos de sonido
A3: Artículos de reparación
A4: Artículos de toro
A5: Gasolina
A6: Herramientas
A7: Impuestos
A8: Mantenimiento almacén
A9: Publicidad
A10: Renta Sonido
A11: Reparación audio
A12: Reparaciones extra
... A18: Suministros audio

Sheet TRABAJADORES
A1: NOMBRE | B1: EDAD
A2: Jesús
A3: Angel
A4: Carlos
A5: Sebastián
A6: Jesualdo
A7: Rodrigo
A8: Marco
A9: Juan
A10: Alejandro
A11: Axel
A12: Ricardo

Sheet LISTA SALARIOS
A1: CONCEPTO | B1: SALARIO
A2: Instalar toro | B2: 100
A3: Recoger toro | B3: 100
A4: Instalar y recoger toro | B4: 200
A5: 1 hora toro | B5: 150
A6: 2 horas toro | B6: 250
A7: 3 horas toro | B7: 350
A8: 4 horas toro | B8: 450
A9: 5 horas toro | B9: 550
A10: 6 horas toro | B10: 650
A11: Spiderman cubo dejar | B11: 45
A12: Spiderman cubo recoger | B12: 45
A13: Spiderman cubo solo | B13: 90
... A149: Comisión diamante | B149: 400

Sheet SALARIOS TORO
A1: Descripción | B1: Salario
A2: Instalar toro | B2: 100
A3: Recoger toro | B3: 100
A4: 1 hora | B4: 150
A5: 2 horas | B5: 250
A6: 3 horas | B6: 350
A7: 4 horas | B7: 450
A8: 5 horas | B8: 550
A9: 6 horas | B9: 650

Sheet SOCIOS
A1: NOMBRE
A2: Angel
A3: Sebastián
A4: Carlos

Sheet SALARIOS INFLABLES
A1: Modelo | B1: Salario
A2: Spiderman cubo dejar | B2: 45
A3: Spiderman cubo recoger | B3: 45
A4: Spiderman cubo solo | B4: 90
A5: Mickey dejar | B5: 45
A6: Mickey recoger | B6: 45
A7: MIckey solo | B7: 90
A8: Princesas dejar | B8: 45
A9: Princesas recoger | B9: 45
A10: Princesas solo | B10: 90
A11: Castillo dejar | B11: 50
A12: Castillo recoger | B12: 50
A13: Castillo solo | B13: 100
... A30: Obstaculos recoger | B30: 75

Sheet SALARIOS SONIDO
A1: Descripción | B1: Salario
A2: Party solo | B2: 990
A3: Party dj animador | B3: 654
A4: Party dj acompañado | B4: 504
A5: Party acompañante | B5: 336
A6: Party animador | B6: 486
A7: Party hora extra | B7: 100
A8: Plata solo | B8: 1140
A9: Plata dj animador | B9: 744
A10: Plata dj acompañado | B10: 594
A11: Plata acompañante | B11: 396
A12: Plata animador | B12: 546
A13: Plata hora extra | B13: 100
... A39: Diamante hora extra | B39: 200

Sheet LISTAS PRECIOS
A1: DESCRIPCIÓN | B1: COSTO
A2: 1 hora toro | B2: 1300
A3: 2 horas toro | B3: 2200
A4: 3 horas toro | B4: 2600
A5: 4 horas toro | B5: 3000
A6: 5 horas toro | B6: 3750
A7: 6 horas toro | B7: 4500
A8: Spiderman_cubo | B8: 600
A9: Mickey | B9: 600
A10: Minions | B10: 650
A11: Princesas | B11: 650
A12: Castillo | B12: 650
A13: Spiderman_circular | B13: 800
... A35: 4 HORAS BOTARGA | B35: 3600

Sheet SALARIOS PISTA
A1: Medidas | B1: Salario
A2: 3x4 instalar | B2: 225
A3: 3x4 desmontar | B3: 225
A4: 4x4 instalar | B4: 200
A5: 4x4 desmontar | B5: 200
A6: 5x4 instalar | B6: 325
A7: 5x4 desmontar | B7: 325
A8: 7x6 instalar | B8: 525
A9: 7x6 desmontar | B9: 525

Sheet SALARIOS BOTARGA
A1: Horas | B1: salario
A2: 1 hora botarga | B2: 300
A3: 2 horas botarga | B3: 600
A4: 3 horas botarga | B4: 900
A5: 4 horas botarga | B5: 1200
A6: 5 horas botarga | B6: 1500

Sheet BONOS Y COMISIONES
A1: DESCRIPCIÓN | B1: MONTO
A2: Gerente | B2: 250
A3: Bono semanal | B3: 100
A4: Bono noche | B4: 100
A5: Comision spiderman | B5: 60
A6: Comisión mickey | B6: 60
A7: Comisión princesas | B7: 60
A8: Comisión minions | B8: 70
A9: Comisión castillo | B9: 70
A10: Comisión spiderman c | B10: 80
A11: Comisión superheroes | B11: 80
A12: Comisión barbie | B12: 80
A13: Comisión princesas c | B13: 80
... A24: Comisión diamante | B24: 400

Sheet SERVICIOS
A1: ID | B1: SERVICIO
A2: S01 | B2: Toro
A3: S02 | B3: Inflable
A4: S03 | B4: Sonido
A5: S04 | B5: Pista
A6: S05 | B6: Botarga
A7: S06 | B7: Bono

Sheet TARIFAS TORO
A1: HORAS | B1: PRECIO
A2: 1 HORA TORO | B2: 1300
A3: 2 HORAS TORO | B3: 2200
A4: 3 HORAS TORO | B4: 2600
A5: 4 HORAS TORO | B5: 3000
A6: 5 HORAS TORO | B6: 3750
A7: 6 HORAS TORO | B7: 4500

Sheet TARIFAS INFLABLES
A1: MODELO | B1: PRECIO
A2: Spiderman_cubo | B2: 600
A3: Mickey | B3: 600
A4: Minions | B4: 650
A5: Princesas | B5: 650
A6: Castillo | B6: 650
A7: Spiderman_circular | B7: 800
A8: Barbie | B8: 800
A9: Princesas_circular | B9: 800
A10: Superheróes | B10: 800
A11: Obstaculos | B11: 1000

Sheet TARIFAS SONIDO
A1: PAQUETE | B1: PRECIO
A2: Party | B2: 2800
A3: Plata | B3: 3300
A4: Chiquidisco | B4: 3600
A5: Deluxe | B5: 4000
A6: Premium | B6: 4700
A7: Oro | B7: 5500
A8: Diamante | B8: 6000

Sheet TARIFAS PISTA
A1: TAMAÑO | B1: PRECIO
A2: 3x4 | B2: 3000
A3: 4x4 | B3: 4000
A4: 5x4 | B4: 5000
A5: 7x6 | B5: 7000

Sheet TARIFAS BOTARGA
A1: HORAS | B1: PRECIO
A2: 1 | B2: 800
A3: 2 | B3: 1600
A4: 3 | B4: 2400
A5: 4 | B5: 3600
